[2022-10-14 14:54:36,722] {taskinstance.py:1179} INFO - Dependencies all met for <TaskInstance: generate_data.generate_data scheduled__2022-10-14T14:44:59.259089+00:00 [queued]>
[2022-10-14 14:54:36,804] {taskinstance.py:1179} INFO - Dependencies all met for <TaskInstance: generate_data.generate_data scheduled__2022-10-14T14:44:59.259089+00:00 [queued]>
[2022-10-14 14:54:36,807] {taskinstance.py:1376} INFO - 
--------------------------------------------------------------------------------
[2022-10-14 14:54:36,811] {taskinstance.py:1377} INFO - Starting attempt 2 of 2
[2022-10-14 14:54:36,816] {taskinstance.py:1378} INFO - 
--------------------------------------------------------------------------------
[2022-10-14 14:54:36,928] {taskinstance.py:1397} INFO - Executing <Task(PythonOperator): generate_data> on 2022-10-14 14:44:59.259089+00:00
[2022-10-14 14:54:36,958] {standard_task_runner.py:52} INFO - Started process 22379 to run task
[2022-10-14 14:54:36,996] {standard_task_runner.py:79} INFO - Running: ['***', 'tasks', 'run', 'generate_data', 'generate_data', 'scheduled__2022-10-14T14:44:59.259089+00:00', '--job-id', '51', '--raw', '--subdir', 'DAGS_FOLDER/generate_data.py', '--cfg-path', '/tmp/tmpjcd18n82', '--error-file', '/tmp/tmpntkutop5']
[2022-10-14 14:54:37,011] {standard_task_runner.py:80} INFO - Job 51: Subtask generate_data
[2022-10-14 14:54:37,431] {task_command.py:371} INFO - Running <TaskInstance: generate_data.generate_data scheduled__2022-10-14T14:44:59.259089+00:00 [running]> on host 6b13e7472fb2
[2022-10-14 14:54:37,868] {taskinstance.py:1591} INFO - Exporting the following env vars:
AIRFLOW_CTX_DAG_OWNER=***
AIRFLOW_CTX_DAG_ID=generate_data
AIRFLOW_CTX_TASK_ID=generate_data
AIRFLOW_CTX_EXECUTION_DATE=2022-10-14T14:44:59.259089+00:00
AIRFLOW_CTX_TRY_NUMBER=2
AIRFLOW_CTX_DAG_RUN_ID=scheduled__2022-10-14T14:44:59.259089+00:00
[2022-10-14 14:54:37,926] {db_conn.py:23} INFO - Connection to database success
[2022-10-14 14:54:38,043] {insertion_factory.py:41} CRITICAL - <class 'RecursionError'>
[2022-10-14 14:54:38,046] {insertion_factory.py:42} CRITICAL - maximum recursion depth exceeded while calling a Python object
[2022-10-14 14:54:38,050] {insertion_factory.py:43} CRITICAL - Insertion into database failed, check params.
[2022-10-14 14:54:38,058] {logging_mixin.py:115} INFO - Generating jsonline: 1
[2022-10-14 14:54:38,185] {taskinstance.py:1909} ERROR - Task failed with exception
Traceback (most recent call last):
  File "/home/airflow/.local/lib/python3.7/site-packages/airflow/operators/python.py", line 171, in execute
    return_value = self.execute_callable()
  File "/home/airflow/.local/lib/python3.7/site-packages/airflow/operators/python.py", line 189, in execute_callable
    return self.python_callable(*self.op_args, **self.op_kwargs)
  File "/opt/airflow/dags/insertion_orchestration.py", line 34, in gen_data
    jf.generate_jsonlines(n_lines=insertions, days= days)
  File "/opt/airflow/dags/json_factory.py", line 22, in generate_jsonlines
    id = ID.get_id(dict_ids = ids)
  File "/opt/airflow/dags/id_loader.py", line 35, in get_id
    return get_id(dict_ids)
  File "/opt/airflow/dags/id_loader.py", line 35, in get_id
    return get_id(dict_ids)
  File "/opt/airflow/dags/id_loader.py", line 35, in get_id
    return get_id(dict_ids)
  [Previous line repeated 929 more times]
  File "/opt/airflow/dags/id_loader.py", line 29, in get_id
    key, value = random.choice(list(dict_ids.items()))
  File "/usr/local/lib/python3.7/random.py", line 259, in choice
    i = self._randbelow(len(seq))
  File "/usr/local/lib/python3.7/random.py", line 232, in _randbelow
    if type(random) is BuiltinMethod or type(getrandbits) is Method:
RecursionError: maximum recursion depth exceeded while calling a Python object
[2022-10-14 14:54:38,281] {taskinstance.py:1420} INFO - Marking task as FAILED. dag_id=generate_data, task_id=generate_data, execution_date=20221014T144459, start_date=20221014T145436, end_date=20221014T145438
[2022-10-14 14:54:38,363] {standard_task_runner.py:97} ERROR - Failed to execute job 51 for task generate_data (maximum recursion depth exceeded while calling a Python object; 22379)
[2022-10-14 14:54:38,437] {local_task_job.py:156} INFO - Task exited with return code 1
[2022-10-14 14:54:38,645] {local_task_job.py:273} INFO - 0 downstream tasks scheduled from follow-on schedule check
