[2022-10-24T19:30:23.555+0000] {taskinstance.py:1165} INFO - Dependencies all met for <TaskInstance: unify_datasets.load_and_transform_unified_data manual__2022-10-24T19:12:05.912989+00:00 [failed]>
[2022-10-24T19:30:23.595+0000] {taskinstance.py:1165} INFO - Dependencies all met for <TaskInstance: unify_datasets.load_and_transform_unified_data manual__2022-10-24T19:12:05.912989+00:00 [failed]>
[2022-10-24T19:30:23.597+0000] {taskinstance.py:1362} INFO - 
--------------------------------------------------------------------------------
[2022-10-24T19:30:23.599+0000] {taskinstance.py:1363} INFO - Starting attempt 5 of 2
[2022-10-24T19:30:23.603+0000] {taskinstance.py:1364} INFO - 
--------------------------------------------------------------------------------
[2022-10-24T19:30:23.656+0000] {taskinstance.py:1383} INFO - Executing <Task(PythonOperator): load_and_transform_unified_data> on 2022-10-24 19:12:05.912989+00:00
[2022-10-24T19:30:23.678+0000] {standard_task_runner.py:54} INFO - Started process 35599 to run task
[2022-10-24T19:30:23.721+0000] {standard_task_runner.py:82} INFO - Running: ['***', 'tasks', 'run', 'unify_datasets', 'load_and_transform_unified_data', 'manual__2022-10-24T19:12:05.912989+00:00', '--job-id', '547', '--pool', 'default_pool', '--raw', '--subdir', 'DAGS_FOLDER/load_and_unify_datasets.py', '--cfg-path', '/tmp/tmpxrcok2wc']
[2022-10-24T19:30:23.728+0000] {standard_task_runner.py:83} INFO - Job 547: Subtask load_and_transform_unified_data
[2022-10-24T19:30:23.734+0000] {dagbag.py:525} INFO - Filling up the DagBag from /opt/***/dags/load_and_unify_datasets.py
[2022-10-24T19:30:24.117+0000] {task_command.py:384} INFO - Running <TaskInstance: unify_datasets.load_and_transform_unified_data manual__2022-10-24T19:12:05.912989+00:00 [running]> on host c94e224fed05
[2022-10-24T19:30:24.474+0000] {taskinstance.py:1592} INFO - Exporting the following env vars:
AIRFLOW_CTX_DAG_OWNER=***
AIRFLOW_CTX_DAG_ID=unify_datasets
AIRFLOW_CTX_TASK_ID=load_and_transform_unified_data
AIRFLOW_CTX_EXECUTION_DATE=2022-10-24T19:12:05.912989+00:00
AIRFLOW_CTX_TRY_NUMBER=5
AIRFLOW_CTX_DAG_RUN_ID=manual__2022-10-24T19:12:05.912989+00:00
[2022-10-24T19:30:54.443+0000] {taskinstance.py:1851} ERROR - Task failed with exception
Traceback (most recent call last):
  File "/home/airflow/.local/lib/python3.7/site-packages/airflow/operators/python.py", line 175, in execute
    return_value = self.execute_callable()
  File "/home/airflow/.local/lib/python3.7/site-packages/airflow/operators/python.py", line 193, in execute_callable
    return self.python_callable(*self.op_args, **self.op_kwargs)
  File "/opt/airflow/dags/pyspark_scripts.py", line 179, in transform_data
    sc.addFile('pyspark_scripts.py')
  File "/home/airflow/.local/lib/python3.7/site-packages/pyspark/context.py", line 1248, in addFile
    self._jsc.sc().addFile(path, recursive)
  File "/home/airflow/.local/lib/python3.7/site-packages/py4j/java_gateway.py", line 1322, in __call__
    answer, self.gateway_client, self.target_id, self.name)
  File "/home/airflow/.local/lib/python3.7/site-packages/pyspark/sql/utils.py", line 190, in deco
    return f(*a, **kw)
  File "/home/airflow/.local/lib/python3.7/site-packages/py4j/protocol.py", line 328, in get_return_value
    format(target_id, ".", name), value)
py4j.protocol.Py4JJavaError: An error occurred while calling o25.addFile.
: java.io.FileNotFoundException: File file:/opt/airflow/pyspark_scripts.py does not exist
	at org.apache.hadoop.fs.RawLocalFileSystem.deprecatedGetFileStatus(RawLocalFileSystem.java:779)
	at org.apache.hadoop.fs.RawLocalFileSystem.getFileLinkStatusInternal(RawLocalFileSystem.java:1100)
	at org.apache.hadoop.fs.RawLocalFileSystem.getFileStatus(RawLocalFileSystem.java:769)
	at org.apache.hadoop.fs.FilterFileSystem.getFileStatus(FilterFileSystem.java:462)
	at org.apache.spark.SparkContext.addFile(SparkContext.scala:1620)
	at org.apache.spark.SparkContext.addFile(SparkContext.scala:1600)
	at java.base/jdk.internal.reflect.NativeMethodAccessorImpl.invoke0(Native Method)
	at java.base/jdk.internal.reflect.NativeMethodAccessorImpl.invoke(NativeMethodAccessorImpl.java:62)
	at java.base/jdk.internal.reflect.DelegatingMethodAccessorImpl.invoke(DelegatingMethodAccessorImpl.java:43)
	at java.base/java.lang.reflect.Method.invoke(Method.java:566)
	at py4j.reflection.MethodInvoker.invoke(MethodInvoker.java:244)
	at py4j.reflection.ReflectionEngine.invoke(ReflectionEngine.java:357)
	at py4j.Gateway.invoke(Gateway.java:282)
	at py4j.commands.AbstractCommand.invokeMethod(AbstractCommand.java:132)
	at py4j.commands.CallCommand.execute(CallCommand.java:79)
	at py4j.ClientServerConnection.waitForCommands(ClientServerConnection.java:182)
	at py4j.ClientServerConnection.run(ClientServerConnection.java:106)
	at java.base/java.lang.Thread.run(Thread.java:829)

[2022-10-24T19:30:54.489+0000] {taskinstance.py:1406} INFO - Marking task as FAILED. dag_id=unify_datasets, task_id=load_and_transform_unified_data, execution_date=20221024T191205, start_date=20221024T193023, end_date=20221024T193054
[2022-10-24T19:30:54.588+0000] {standard_task_runner.py:107} ERROR - Failed to execute job 547 for task load_and_transform_unified_data (An error occurred while calling o25.addFile.
: java.io.FileNotFoundException: File file:/opt/airflow/pyspark_scripts.py does not exist
	at org.apache.hadoop.fs.RawLocalFileSystem.deprecatedGetFileStatus(RawLocalFileSystem.java:779)
	at org.apache.hadoop.fs.RawLocalFileSystem.getFileLinkStatusInternal(RawLocalFileSystem.java:1100)
	at org.apache.hadoop.fs.RawLocalFileSystem.getFileStatus(RawLocalFileSystem.java:769)
	at org.apache.hadoop.fs.FilterFileSystem.getFileStatus(FilterFileSystem.java:462)
	at org.apache.spark.SparkContext.addFile(SparkContext.scala:1620)
	at org.apache.spark.SparkContext.addFile(SparkContext.scala:1600)
	at java.base/jdk.internal.reflect.NativeMethodAccessorImpl.invoke0(Native Method)
	at java.base/jdk.internal.reflect.NativeMethodAccessorImpl.invoke(NativeMethodAccessorImpl.java:62)
	at java.base/jdk.internal.reflect.DelegatingMethodAccessorImpl.invoke(DelegatingMethodAccessorImpl.java:43)
	at java.base/java.lang.reflect.Method.invoke(Method.java:566)
	at py4j.reflection.MethodInvoker.invoke(MethodInvoker.java:244)
	at py4j.reflection.ReflectionEngine.invoke(ReflectionEngine.java:357)
	at py4j.Gateway.invoke(Gateway.java:282)
	at py4j.commands.AbstractCommand.invokeMethod(AbstractCommand.java:132)
	at py4j.commands.CallCommand.execute(CallCommand.java:79)
	at py4j.ClientServerConnection.waitForCommands(ClientServerConnection.java:182)
	at py4j.ClientServerConnection.run(ClientServerConnection.java:106)
	at java.base/java.lang.Thread.run(Thread.java:829)
; 35599)
[2022-10-24T19:30:54.667+0000] {local_task_job.py:164} INFO - Task exited with return code 1
[2022-10-24T19:30:54.800+0000] {local_task_job.py:273} INFO - 0 downstream tasks scheduled from follow-on schedule check
