[2022-10-24T19:40:49.764+0000] {taskinstance.py:1165} INFO - Dependencies all met for <TaskInstance: unify_datasets.load_and_transform_unified_data manual__2022-10-24T19:12:05.912989+00:00 [failed]>
[2022-10-24T19:40:49.802+0000] {taskinstance.py:1165} INFO - Dependencies all met for <TaskInstance: unify_datasets.load_and_transform_unified_data manual__2022-10-24T19:12:05.912989+00:00 [failed]>
[2022-10-24T19:40:49.803+0000] {taskinstance.py:1362} INFO - 
--------------------------------------------------------------------------------
[2022-10-24T19:40:49.805+0000] {taskinstance.py:1363} INFO - Starting attempt 7 of 2
[2022-10-24T19:40:49.806+0000] {taskinstance.py:1364} INFO - 
--------------------------------------------------------------------------------
[2022-10-24T19:40:49.828+0000] {taskinstance.py:1383} INFO - Executing <Task(PythonOperator): load_and_transform_unified_data> on 2022-10-24 19:12:05.912989+00:00
[2022-10-24T19:40:49.844+0000] {standard_task_runner.py:54} INFO - Started process 39414 to run task
[2022-10-24T19:40:49.857+0000] {standard_task_runner.py:82} INFO - Running: ['***', 'tasks', 'run', 'unify_datasets', 'load_and_transform_unified_data', 'manual__2022-10-24T19:12:05.912989+00:00', '--job-id', '549', '--pool', 'default_pool', '--raw', '--subdir', 'DAGS_FOLDER/load_and_unify_datasets.py', '--cfg-path', '/tmp/tmpv_i9ydr1']
[2022-10-24T19:40:49.859+0000] {standard_task_runner.py:83} INFO - Job 549: Subtask load_and_transform_unified_data
[2022-10-24T19:40:49.863+0000] {dagbag.py:525} INFO - Filling up the DagBag from /opt/***/dags/load_and_unify_datasets.py
[2022-10-24T19:40:50.104+0000] {task_command.py:384} INFO - Running <TaskInstance: unify_datasets.load_and_transform_unified_data manual__2022-10-24T19:12:05.912989+00:00 [running]> on host c94e224fed05
[2022-10-24T19:40:50.353+0000] {taskinstance.py:1592} INFO - Exporting the following env vars:
AIRFLOW_CTX_DAG_OWNER=***
AIRFLOW_CTX_DAG_ID=unify_datasets
AIRFLOW_CTX_TASK_ID=load_and_transform_unified_data
AIRFLOW_CTX_EXECUTION_DATE=2022-10-24T19:12:05.912989+00:00
AIRFLOW_CTX_TRY_NUMBER=7
AIRFLOW_CTX_DAG_RUN_ID=manual__2022-10-24T19:12:05.912989+00:00
[2022-10-24T19:41:30.378+0000] {pyspark_scripts.py:186} INFO - Dump DF
[2022-10-24T19:41:39.556+0000] {taskinstance.py:1851} ERROR - Task failed with exception
Traceback (most recent call last):
  File "/home/airflow/.local/lib/python3.7/site-packages/airflow/operators/python.py", line 175, in execute
    return_value = self.execute_callable()
  File "/home/airflow/.local/lib/python3.7/site-packages/airflow/operators/python.py", line 193, in execute_callable
    return self.python_callable(*self.op_args, **self.op_kwargs)
  File "/opt/airflow/dags/pyspark_scripts.py", line 188, in transform_data
    dump_df.show(10)
  File "/home/airflow/.local/lib/python3.7/site-packages/pyspark/sql/dataframe.py", line 606, in show
    print(self._jdf.showString(n, 20, vertical))
  File "/home/airflow/.local/lib/python3.7/site-packages/py4j/java_gateway.py", line 1322, in __call__
    answer, self.gateway_client, self.target_id, self.name)
  File "/home/airflow/.local/lib/python3.7/site-packages/pyspark/sql/utils.py", line 196, in deco
    raise converted from None
pyspark.sql.utils.PythonException: 
  An exception was thrown from the Python worker. Please see the stack trace below.
Traceback (most recent call last):
  File "/opt/airflow/dags/pyspark_scripts.py", line 178, in amount
    return catalog_sc.value.transform_amount(x)
TypeError: transform_amount() takes 1 positional argument but 2 were given

[2022-10-24T19:41:39.740+0000] {taskinstance.py:1406} INFO - Marking task as FAILED. dag_id=unify_datasets, task_id=load_and_transform_unified_data, execution_date=20221024T191205, start_date=20221024T194049, end_date=20221024T194139
[2022-10-24T19:41:39.926+0000] {standard_task_runner.py:107} ERROR - Failed to execute job 549 for task load_and_transform_unified_data (
  An exception was thrown from the Python worker. Please see the stack trace below.
Traceback (most recent call last):
  File "/opt/airflow/dags/pyspark_scripts.py", line 178, in amount
    return catalog_sc.value.transform_amount(x)
TypeError: transform_amount() takes 1 positional argument but 2 were given
; 39414)
[2022-10-24T19:41:40.233+0000] {local_task_job.py:164} INFO - Task exited with return code 1
[2022-10-24T19:41:40.400+0000] {local_task_job.py:273} INFO - 0 downstream tasks scheduled from follow-on schedule check
