[2022-10-16 04:44:02,873] {taskinstance.py:1179} INFO - Dependencies all met for <TaskInstance: generate_data.generate_data scheduled__2022-10-16T04:29:03.845556+00:00 [queued]>
[2022-10-16 04:44:03,016] {taskinstance.py:1179} INFO - Dependencies all met for <TaskInstance: generate_data.generate_data scheduled__2022-10-16T04:29:03.845556+00:00 [queued]>
[2022-10-16 04:44:03,022] {taskinstance.py:1376} INFO - 
--------------------------------------------------------------------------------
[2022-10-16 04:44:03,026] {taskinstance.py:1377} INFO - Starting attempt 2 of 2
[2022-10-16 04:44:03,030] {taskinstance.py:1378} INFO - 
--------------------------------------------------------------------------------
[2022-10-16 04:44:03,615] {taskinstance.py:1397} INFO - Executing <Task(PythonOperator): generate_data> on 2022-10-16 04:29:03.845556+00:00
[2022-10-16 04:44:03,711] {standard_task_runner.py:52} INFO - Started process 30167 to run task
[2022-10-16 04:44:03,899] {standard_task_runner.py:79} INFO - Running: ['***', 'tasks', 'run', 'generate_data', 'generate_data', 'scheduled__2022-10-16T04:29:03.845556+00:00', '--job-id', '264', '--raw', '--subdir', 'DAGS_FOLDER/generate_data.py', '--cfg-path', '/tmp/tmpzz8o2x6o', '--error-file', '/tmp/tmp1uwd6_9q']
[2022-10-16 04:44:03,942] {standard_task_runner.py:80} INFO - Job 264: Subtask generate_data
[2022-10-16 04:44:04,968] {task_command.py:371} INFO - Running <TaskInstance: generate_data.generate_data scheduled__2022-10-16T04:29:03.845556+00:00 [running]> on host 614e96fbdf07
[2022-10-16 04:44:06,939] {taskinstance.py:1591} INFO - Exporting the following env vars:
AIRFLOW_CTX_DAG_OWNER=***
AIRFLOW_CTX_DAG_ID=generate_data
AIRFLOW_CTX_TASK_ID=generate_data
AIRFLOW_CTX_EXECUTION_DATE=2022-10-16T04:29:03.845556+00:00
AIRFLOW_CTX_TRY_NUMBER=2
AIRFLOW_CTX_DAG_RUN_ID=scheduled__2022-10-16T04:29:03.845556+00:00
[2022-10-16 04:44:07,331] {db_conn.py:23} INFO - Connection to database success
[2022-10-16 04:44:08,153] {insertion_factory.py:41} CRITICAL - <class 'RecursionError'>
[2022-10-16 04:44:08,158] {insertion_factory.py:42} CRITICAL - maximum recursion depth exceeded while calling a Python object
[2022-10-16 04:44:08,163] {insertion_factory.py:43} CRITICAL - Insertion into database failed, check params.
[2022-10-16 04:44:08,184] {logging_mixin.py:115} INFO - Generating jsonline: 1
[2022-10-16 04:44:08,880] {taskinstance.py:1909} ERROR - Task failed with exception
Traceback (most recent call last):
  File "/home/airflow/.local/lib/python3.7/site-packages/airflow/operators/python.py", line 171, in execute
    return_value = self.execute_callable()
  File "/home/airflow/.local/lib/python3.7/site-packages/airflow/operators/python.py", line 189, in execute_callable
    return self.python_callable(*self.op_args, **self.op_kwargs)
  File "/opt/airflow/dags/insertion_orchestration.py", line 34, in gen_data
    jf.generate_jsonlines(n_lines=insertions, days= days)
  File "/opt/airflow/dags/json_factory.py", line 22, in generate_jsonlines
    id = ID.get_id(dict_ids = ids)
  File "/opt/airflow/dags/id_loader.py", line 35, in get_id
    return get_id(dict_ids)
  File "/opt/airflow/dags/id_loader.py", line 35, in get_id
    return get_id(dict_ids)
  File "/opt/airflow/dags/id_loader.py", line 35, in get_id
    return get_id(dict_ids)
  [Previous line repeated 929 more times]
  File "/opt/airflow/dags/id_loader.py", line 29, in get_id
    key, value = random.choice(list(dict_ids.items()))
  File "/usr/local/lib/python3.7/random.py", line 259, in choice
    i = self._randbelow(len(seq))
  File "/usr/local/lib/python3.7/random.py", line 232, in _randbelow
    if type(random) is BuiltinMethod or type(getrandbits) is Method:
RecursionError: maximum recursion depth exceeded while calling a Python object
[2022-10-16 04:44:09,620] {taskinstance.py:1420} INFO - Marking task as FAILED. dag_id=generate_data, task_id=generate_data, execution_date=20221016T042903, start_date=20221016T044402, end_date=20221016T044409
[2022-10-16 04:44:09,941] {standard_task_runner.py:97} ERROR - Failed to execute job 264 for task generate_data (maximum recursion depth exceeded while calling a Python object; 30167)
[2022-10-16 04:44:10,120] {local_task_job.py:221} WARNING - State of this instance has been externally set to failed. Terminating instance.
[2022-10-16 04:44:10,204] {process_utils.py:129} INFO - Sending Signals.SIGTERM to group 30167. PIDs of all processes in the group: [30167]
[2022-10-16 04:44:10,221] {process_utils.py:80} INFO - Sending the signal Signals.SIGTERM to group 30167
[2022-10-16 04:44:10,319] {process_utils.py:75} INFO - Process psutil.Process(pid=30167, status='terminated', exitcode=1, started='04:44:02') (30167) terminated with exit code 1
