[2022-10-16 07:49:16,895] {taskinstance.py:1179} INFO - Dependencies all met for <TaskInstance: generate_data.generate_data scheduled__2022-10-16T07:39:21.092201+00:00 [queued]>
[2022-10-16 07:49:16,988] {taskinstance.py:1179} INFO - Dependencies all met for <TaskInstance: generate_data.generate_data scheduled__2022-10-16T07:39:21.092201+00:00 [queued]>
[2022-10-16 07:49:16,993] {taskinstance.py:1376} INFO - 
--------------------------------------------------------------------------------
[2022-10-16 07:49:16,997] {taskinstance.py:1377} INFO - Starting attempt 2 of 2
[2022-10-16 07:49:17,001] {taskinstance.py:1378} INFO - 
--------------------------------------------------------------------------------
[2022-10-16 07:49:17,112] {taskinstance.py:1397} INFO - Executing <Task(PythonOperator): generate_data> on 2022-10-16 07:39:21.092201+00:00
[2022-10-16 07:49:17,166] {standard_task_runner.py:52} INFO - Started process 32055 to run task
[2022-10-16 07:49:17,218] {standard_task_runner.py:79} INFO - Running: ['***', 'tasks', 'run', 'generate_data', 'generate_data', 'scheduled__2022-10-16T07:39:21.092201+00:00', '--job-id', '280', '--raw', '--subdir', 'DAGS_FOLDER/generate_data.py', '--cfg-path', '/tmp/tmpg7gm2jb4', '--error-file', '/tmp/tmpo8jl85k_']
[2022-10-16 07:49:17,235] {standard_task_runner.py:80} INFO - Job 280: Subtask generate_data
[2022-10-16 07:49:17,941] {task_command.py:371} INFO - Running <TaskInstance: generate_data.generate_data scheduled__2022-10-16T07:39:21.092201+00:00 [running]> on host 614e96fbdf07
[2022-10-16 07:49:18,647] {taskinstance.py:1591} INFO - Exporting the following env vars:
AIRFLOW_CTX_DAG_OWNER=***
AIRFLOW_CTX_DAG_ID=generate_data
AIRFLOW_CTX_TASK_ID=generate_data
AIRFLOW_CTX_EXECUTION_DATE=2022-10-16T07:39:21.092201+00:00
AIRFLOW_CTX_TRY_NUMBER=2
AIRFLOW_CTX_DAG_RUN_ID=scheduled__2022-10-16T07:39:21.092201+00:00
[2022-10-16 07:49:18,745] {db_conn.py:23} INFO - Connection to database success
[2022-10-16 07:49:18,949] {insertion_factory.py:41} CRITICAL - <class 'RecursionError'>
[2022-10-16 07:49:18,961] {insertion_factory.py:42} CRITICAL - maximum recursion depth exceeded while calling a Python object
[2022-10-16 07:49:18,965] {insertion_factory.py:43} CRITICAL - Insertion into database failed, check params.
[2022-10-16 07:49:18,977] {logging_mixin.py:115} INFO - Generating jsonline: 1
[2022-10-16 07:49:19,122] {taskinstance.py:1909} ERROR - Task failed with exception
Traceback (most recent call last):
  File "/home/airflow/.local/lib/python3.7/site-packages/airflow/operators/python.py", line 171, in execute
    return_value = self.execute_callable()
  File "/home/airflow/.local/lib/python3.7/site-packages/airflow/operators/python.py", line 189, in execute_callable
    return self.python_callable(*self.op_args, **self.op_kwargs)
  File "/opt/airflow/dags/insertion_orchestration.py", line 34, in gen_data
    jf.generate_jsonlines(n_lines=insertions, days= days)
  File "/opt/airflow/dags/json_factory.py", line 22, in generate_jsonlines
    id = ID.get_id(dict_ids = ids)
  File "/opt/airflow/dags/id_loader.py", line 35, in get_id
    return get_id(dict_ids)
  File "/opt/airflow/dags/id_loader.py", line 35, in get_id
    return get_id(dict_ids)
  File "/opt/airflow/dags/id_loader.py", line 35, in get_id
    return get_id(dict_ids)
  [Previous line repeated 929 more times]
  File "/opt/airflow/dags/id_loader.py", line 29, in get_id
    key, value = random.choice(list(dict_ids.items()))
  File "/usr/local/lib/python3.7/random.py", line 259, in choice
    i = self._randbelow(len(seq))
  File "/usr/local/lib/python3.7/random.py", line 232, in _randbelow
    if type(random) is BuiltinMethod or type(getrandbits) is Method:
RecursionError: maximum recursion depth exceeded while calling a Python object
[2022-10-16 07:49:19,226] {taskinstance.py:1420} INFO - Marking task as FAILED. dag_id=generate_data, task_id=generate_data, execution_date=20221016T073921, start_date=20221016T074916, end_date=20221016T074919
[2022-10-16 07:49:19,316] {standard_task_runner.py:97} ERROR - Failed to execute job 280 for task generate_data (maximum recursion depth exceeded while calling a Python object; 32055)
[2022-10-16 07:49:19,420] {local_task_job.py:156} INFO - Task exited with return code 1
[2022-10-16 07:49:19,675] {local_task_job.py:273} INFO - 0 downstream tasks scheduled from follow-on schedule check
