[2022-10-14 23:25:20,052] {taskinstance.py:1179} INFO - Dependencies all met for <TaskInstance: generate_data.generate_data scheduled__2022-10-14T23:15:50.433729+00:00 [queued]>
[2022-10-14 23:25:20,725] {taskinstance.py:1179} INFO - Dependencies all met for <TaskInstance: generate_data.generate_data scheduled__2022-10-14T23:15:50.433729+00:00 [queued]>
[2022-10-14 23:25:20,739] {taskinstance.py:1376} INFO - 
--------------------------------------------------------------------------------
[2022-10-14 23:25:20,763] {taskinstance.py:1377} INFO - Starting attempt 1 of 2
[2022-10-14 23:25:20,778] {taskinstance.py:1378} INFO - 
--------------------------------------------------------------------------------
[2022-10-14 23:25:21,693] {taskinstance.py:1397} INFO - Executing <Task(PythonOperator): generate_data> on 2022-10-14 23:15:50.433729+00:00
[2022-10-14 23:25:21,944] {standard_task_runner.py:52} INFO - Started process 9540 to run task
[2022-10-14 23:25:22,255] {standard_task_runner.py:79} INFO - Running: ['***', 'tasks', 'run', 'generate_data', 'generate_data', 'scheduled__2022-10-14T23:15:50.433729+00:00', '--job-id', '119', '--raw', '--subdir', 'DAGS_FOLDER/generate_data.py', '--cfg-path', '/tmp/tmptr8fnc4e', '--error-file', '/tmp/tmp031j0mwj']
[2022-10-14 23:25:22,306] {standard_task_runner.py:80} INFO - Job 119: Subtask generate_data
[2022-10-14 23:25:24,756] {task_command.py:371} INFO - Running <TaskInstance: generate_data.generate_data scheduled__2022-10-14T23:15:50.433729+00:00 [running]> on host 614e96fbdf07
[2022-10-14 23:25:30,445] {taskinstance.py:1591} INFO - Exporting the following env vars:
AIRFLOW_CTX_DAG_OWNER=***
AIRFLOW_CTX_DAG_ID=generate_data
AIRFLOW_CTX_TASK_ID=generate_data
AIRFLOW_CTX_EXECUTION_DATE=2022-10-14T23:15:50.433729+00:00
AIRFLOW_CTX_TRY_NUMBER=1
AIRFLOW_CTX_DAG_RUN_ID=scheduled__2022-10-14T23:15:50.433729+00:00
[2022-10-14 23:25:31,141] {db_conn.py:23} INFO - Connection to database success
[2022-10-14 23:25:31,998] {insertion_factory.py:41} CRITICAL - <class 'RecursionError'>
[2022-10-14 23:25:32,014] {insertion_factory.py:42} CRITICAL - maximum recursion depth exceeded while calling a Python object
[2022-10-14 23:25:32,018] {insertion_factory.py:43} CRITICAL - Insertion into database failed, check params.
[2022-10-14 23:25:32,040] {logging_mixin.py:115} INFO - Generating jsonline: 1
[2022-10-14 23:25:32,970] {taskinstance.py:1909} ERROR - Task failed with exception
Traceback (most recent call last):
  File "/home/airflow/.local/lib/python3.7/site-packages/airflow/operators/python.py", line 171, in execute
    return_value = self.execute_callable()
  File "/home/airflow/.local/lib/python3.7/site-packages/airflow/operators/python.py", line 189, in execute_callable
    return self.python_callable(*self.op_args, **self.op_kwargs)
  File "/opt/airflow/dags/insertion_orchestration.py", line 34, in gen_data
    jf.generate_jsonlines(n_lines=insertions, days= days)
  File "/opt/airflow/dags/json_factory.py", line 22, in generate_jsonlines
    id = ID.get_id(dict_ids = ids)
  File "/opt/airflow/dags/id_loader.py", line 35, in get_id
    return get_id(dict_ids)
  File "/opt/airflow/dags/id_loader.py", line 35, in get_id
    return get_id(dict_ids)
  File "/opt/airflow/dags/id_loader.py", line 35, in get_id
    return get_id(dict_ids)
  [Previous line repeated 929 more times]
  File "/opt/airflow/dags/id_loader.py", line 29, in get_id
    key, value = random.choice(list(dict_ids.items()))
  File "/usr/local/lib/python3.7/random.py", line 259, in choice
    i = self._randbelow(len(seq))
  File "/usr/local/lib/python3.7/random.py", line 232, in _randbelow
    if type(random) is BuiltinMethod or type(getrandbits) is Method:
RecursionError: maximum recursion depth exceeded while calling a Python object
[2022-10-14 23:25:33,277] {taskinstance.py:1420} INFO - Marking task as UP_FOR_RETRY. dag_id=generate_data, task_id=generate_data, execution_date=20221014T231550, start_date=20221014T232520, end_date=20221014T232533
[2022-10-14 23:25:33,520] {standard_task_runner.py:97} ERROR - Failed to execute job 119 for task generate_data (maximum recursion depth exceeded while calling a Python object; 9540)
[2022-10-14 23:25:33,689] {local_task_job.py:156} INFO - Task exited with return code 1
[2022-10-14 23:25:34,303] {local_task_job.py:273} INFO - 0 downstream tasks scheduled from follow-on schedule check
