[2022-10-17 15:55:53,947] {taskinstance.py:1179} INFO - Dependencies all met for <TaskInstance: generate_data.export_tables_to_dir manual__2022-10-17T15:55:48.376423+00:00 [queued]>
[2022-10-17 15:55:53,969] {taskinstance.py:1179} INFO - Dependencies all met for <TaskInstance: generate_data.export_tables_to_dir manual__2022-10-17T15:55:48.376423+00:00 [queued]>
[2022-10-17 15:55:53,970] {taskinstance.py:1376} INFO - 
--------------------------------------------------------------------------------
[2022-10-17 15:55:53,971] {taskinstance.py:1377} INFO - Starting attempt 1 of 2
[2022-10-17 15:55:53,972] {taskinstance.py:1378} INFO - 
--------------------------------------------------------------------------------
[2022-10-17 15:55:53,991] {taskinstance.py:1397} INFO - Executing <Task(PythonOperator): export_tables_to_dir> on 2022-10-17 15:55:48.376423+00:00
[2022-10-17 15:55:54,001] {standard_task_runner.py:52} INFO - Started process 43453 to run task
[2022-10-17 15:55:54,006] {standard_task_runner.py:79} INFO - Running: ['***', 'tasks', 'run', 'generate_data', 'export_tables_to_dir', 'manual__2022-10-17T15:55:48.376423+00:00', '--job-id', '385', '--raw', '--subdir', 'DAGS_FOLDER/generate_data.py', '--cfg-path', '/tmp/tmpup7srz8y', '--error-file', '/tmp/tmp88qlghff']
[2022-10-17 15:55:54,009] {standard_task_runner.py:80} INFO - Job 385: Subtask export_tables_to_dir
[2022-10-17 15:55:54,101] {task_command.py:371} INFO - Running <TaskInstance: generate_data.export_tables_to_dir manual__2022-10-17T15:55:48.376423+00:00 [running]> on host 614e96fbdf07
[2022-10-17 15:55:54,201] {taskinstance.py:1591} INFO - Exporting the following env vars:
AIRFLOW_CTX_DAG_OWNER=***
AIRFLOW_CTX_DAG_ID=generate_data
AIRFLOW_CTX_TASK_ID=export_tables_to_dir
AIRFLOW_CTX_EXECUTION_DATE=2022-10-17T15:55:48.376423+00:00
AIRFLOW_CTX_TRY_NUMBER=1
AIRFLOW_CTX_DAG_RUN_ID=manual__2022-10-17T15:55:48.376423+00:00
[2022-10-17 15:55:54,212] {export_tables.py:37} INFO - Connection to database success
[2022-10-17 15:55:54,215] {export_tables.py:122} INFO - Working on transaction
[2022-10-17 15:55:54,218] {export_tables.py:86} INFO - Exporting 1000 rows into csv.
[2022-10-17 15:55:54,219] {export_tables.py:96} CRITICAL - <class 'FileNotFoundError'>
[2022-10-17 15:55:54,219] {export_tables.py:97} CRITICAL - [Errno 2] No such file or directory: '/opt/transaction/2022-10-17'
[2022-10-17 15:55:54,220] {export_tables.py:98} CRITICAL - Something went wrong at exporting the table to container storage
[2022-10-17 15:55:54,221] {export_tables.py:122} INFO - Working on customer
[2022-10-17 15:55:54,223] {export_tables.py:86} INFO - Exporting 1000 rows into csv.
[2022-10-17 15:55:54,224] {export_tables.py:96} CRITICAL - <class 'FileNotFoundError'>
[2022-10-17 15:55:54,225] {export_tables.py:97} CRITICAL - [Errno 2] No such file or directory: '/opt/customer/2022-10-17'
[2022-10-17 15:55:54,225] {export_tables.py:98} CRITICAL - Something went wrong at exporting the table to container storage
[2022-10-17 15:55:54,227] {export_tables.py:108} INFO - Both cursor and conn closed successfully
[2022-10-17 15:55:54,228] {export_tables.py:129} INFO - Both thables export successfully
[2022-10-17 15:55:54,228] {python.py:173} INFO - Done. Returned value was: None
[2022-10-17 15:55:54,246] {taskinstance.py:1420} INFO - Marking task as SUCCESS. dag_id=generate_data, task_id=export_tables_to_dir, execution_date=20221017T155548, start_date=20221017T155553, end_date=20221017T155554
[2022-10-17 15:55:54,307] {local_task_job.py:156} INFO - Task exited with return code 0
[2022-10-17 15:55:54,380] {local_task_job.py:273} INFO - 0 downstream tasks scheduled from follow-on schedule check
