[2022-10-14 01:49:13,682] {taskinstance.py:1179} INFO - Dependencies all met for <TaskInstance: generate_data.generate_data scheduled__2022-10-14T01:36:33.741876+00:00 [queued]>
[2022-10-14 01:49:13,696] {taskinstance.py:1179} INFO - Dependencies all met for <TaskInstance: generate_data.generate_data scheduled__2022-10-14T01:36:33.741876+00:00 [queued]>
[2022-10-14 01:49:13,699] {taskinstance.py:1376} INFO - 
--------------------------------------------------------------------------------
[2022-10-14 01:49:13,701] {taskinstance.py:1377} INFO - Starting attempt 2 of 2
[2022-10-14 01:49:13,705] {taskinstance.py:1378} INFO - 
--------------------------------------------------------------------------------
[2022-10-14 01:49:13,750] {taskinstance.py:1397} INFO - Executing <Task(PythonOperator): generate_data> on 2022-10-14 01:36:33.741876+00:00
[2022-10-14 01:49:13,761] {standard_task_runner.py:52} INFO - Started process 19240 to run task
[2022-10-14 01:49:13,777] {standard_task_runner.py:79} INFO - Running: ['***', 'tasks', 'run', 'generate_data', 'generate_data', 'scheduled__2022-10-14T01:36:33.741876+00:00', '--job-id', '28', '--raw', '--subdir', 'DAGS_FOLDER/generate_data.py', '--cfg-path', '/tmp/tmplqssib49', '--error-file', '/tmp/tmpkygehp5d']
[2022-10-14 01:49:13,781] {standard_task_runner.py:80} INFO - Job 28: Subtask generate_data
[2022-10-14 01:49:13,952] {task_command.py:371} INFO - Running <TaskInstance: generate_data.generate_data scheduled__2022-10-14T01:36:33.741876+00:00 [running]> on host 6b13e7472fb2
[2022-10-14 01:49:14,096] {taskinstance.py:1591} INFO - Exporting the following env vars:
AIRFLOW_CTX_DAG_OWNER=***
AIRFLOW_CTX_DAG_ID=generate_data
AIRFLOW_CTX_TASK_ID=generate_data
AIRFLOW_CTX_EXECUTION_DATE=2022-10-14T01:36:33.741876+00:00
AIRFLOW_CTX_TRY_NUMBER=2
AIRFLOW_CTX_DAG_RUN_ID=scheduled__2022-10-14T01:36:33.741876+00:00
[2022-10-14 01:49:14,119] {db_conn.py:23} INFO - Connection to database success
[2022-10-14 01:49:14,159] {insertion_factory.py:41} CRITICAL - <class 'RecursionError'>
[2022-10-14 01:49:14,160] {insertion_factory.py:42} CRITICAL - maximum recursion depth exceeded while calling a Python object
[2022-10-14 01:49:14,161] {insertion_factory.py:43} CRITICAL - Insertion into database failed, check params.
[2022-10-14 01:49:14,163] {logging_mixin.py:115} INFO - Generating jsonline: 1
[2022-10-14 01:49:14,190] {taskinstance.py:1909} ERROR - Task failed with exception
Traceback (most recent call last):
  File "/home/airflow/.local/lib/python3.7/site-packages/airflow/operators/python.py", line 171, in execute
    return_value = self.execute_callable()
  File "/home/airflow/.local/lib/python3.7/site-packages/airflow/operators/python.py", line 189, in execute_callable
    return self.python_callable(*self.op_args, **self.op_kwargs)
  File "/opt/airflow/dags/insertion_orchestration.py", line 34, in gen_data
    jf.generate_jsonlines(n_lines=insertions, days= days)
  File "/opt/airflow/dags/json_factory.py", line 22, in generate_jsonlines
    id = ID.get_id(dict_ids = ids)
  File "/opt/airflow/dags/id_loader.py", line 35, in get_id
    return get_id(dict_ids)
  File "/opt/airflow/dags/id_loader.py", line 35, in get_id
    return get_id(dict_ids)
  File "/opt/airflow/dags/id_loader.py", line 35, in get_id
    return get_id(dict_ids)
  [Previous line repeated 929 more times]
  File "/opt/airflow/dags/id_loader.py", line 29, in get_id
    key, value = random.choice(list(dict_ids.items()))
  File "/usr/local/lib/python3.7/random.py", line 259, in choice
    i = self._randbelow(len(seq))
  File "/usr/local/lib/python3.7/random.py", line 232, in _randbelow
    if type(random) is BuiltinMethod or type(getrandbits) is Method:
RecursionError: maximum recursion depth exceeded while calling a Python object
[2022-10-14 01:49:14,241] {taskinstance.py:1420} INFO - Marking task as FAILED. dag_id=generate_data, task_id=generate_data, execution_date=20221014T013633, start_date=20221014T014913, end_date=20221014T014914
[2022-10-14 01:49:14,319] {standard_task_runner.py:97} ERROR - Failed to execute job 28 for task generate_data (maximum recursion depth exceeded while calling a Python object; 19240)
[2022-10-14 01:49:14,399] {local_task_job.py:156} INFO - Task exited with return code 1
[2022-10-14 01:49:14,458] {local_task_job.py:273} INFO - 0 downstream tasks scheduled from follow-on schedule check
