[2022-10-14 19:47:26,807] {taskinstance.py:1179} INFO - Dependencies all met for <TaskInstance: generate_data.export_tables_to_dir manual__2022-10-14T19:47:19.742216+00:00 [queued]>
[2022-10-14 19:47:26,821] {taskinstance.py:1179} INFO - Dependencies all met for <TaskInstance: generate_data.export_tables_to_dir manual__2022-10-14T19:47:19.742216+00:00 [queued]>
[2022-10-14 19:47:26,822] {taskinstance.py:1376} INFO - 
--------------------------------------------------------------------------------
[2022-10-14 19:47:26,823] {taskinstance.py:1377} INFO - Starting attempt 1 of 2
[2022-10-14 19:47:26,824] {taskinstance.py:1378} INFO - 
--------------------------------------------------------------------------------
[2022-10-14 19:47:26,846] {taskinstance.py:1397} INFO - Executing <Task(PythonOperator): export_tables_to_dir> on 2022-10-14 19:47:19.742216+00:00
[2022-10-14 19:47:26,859] {standard_task_runner.py:52} INFO - Started process 3291 to run task
[2022-10-14 19:47:26,867] {standard_task_runner.py:79} INFO - Running: ['***', 'tasks', 'run', 'generate_data', 'export_tables_to_dir', 'manual__2022-10-14T19:47:19.742216+00:00', '--job-id', '106', '--raw', '--subdir', 'DAGS_FOLDER/generate_data.py', '--cfg-path', '/tmp/tmph0swf0px', '--error-file', '/tmp/tmprl6_mz3r']
[2022-10-14 19:47:26,883] {standard_task_runner.py:80} INFO - Job 106: Subtask export_tables_to_dir
[2022-10-14 19:47:27,060] {task_command.py:371} INFO - Running <TaskInstance: generate_data.export_tables_to_dir manual__2022-10-14T19:47:19.742216+00:00 [running]> on host 614e96fbdf07
[2022-10-14 19:47:27,425] {taskinstance.py:1591} INFO - Exporting the following env vars:
AIRFLOW_CTX_DAG_OWNER=***
AIRFLOW_CTX_DAG_ID=generate_data
AIRFLOW_CTX_TASK_ID=export_tables_to_dir
AIRFLOW_CTX_EXECUTION_DATE=2022-10-14T19:47:19.742216+00:00
AIRFLOW_CTX_TRY_NUMBER=1
AIRFLOW_CTX_DAG_RUN_ID=manual__2022-10-14T19:47:19.742216+00:00
[2022-10-14 19:47:27,441] {export_tables.py:37} INFO - Connection to database success
[2022-10-14 19:47:27,457] {export_tables.py:120} INFO - Working on transaction
[2022-10-14 19:47:27,463] {export_tables.py:86} INFO - Exporting 500 rows into csv.
[2022-10-14 19:47:27,469] {export_tables.py:96} CRITICAL - Something went wrong at exporting the table to container storage
[2022-10-14 19:47:27,471] {export_tables.py:120} INFO - Working on customer
[2022-10-14 19:47:27,474] {export_tables.py:86} INFO - Exporting 500 rows into csv.
[2022-10-14 19:47:27,475] {export_tables.py:96} CRITICAL - Something went wrong at exporting the table to container storage
[2022-10-14 19:47:27,477] {export_tables.py:106} INFO - Both cursor and conn closed successfully
[2022-10-14 19:47:27,481] {export_tables.py:127} INFO - Both thables export successfully
[2022-10-14 19:47:27,492] {python.py:173} INFO - Done. Returned value was: None
[2022-10-14 19:47:27,549] {taskinstance.py:1420} INFO - Marking task as SUCCESS. dag_id=generate_data, task_id=export_tables_to_dir, execution_date=20221014T194719, start_date=20221014T194726, end_date=20221014T194727
[2022-10-14 19:47:27,654] {local_task_job.py:156} INFO - Task exited with return code 0
[2022-10-14 19:47:27,767] {local_task_job.py:273} INFO - 0 downstream tasks scheduled from follow-on schedule check
