[2022-10-14 16:34:56,744] {taskinstance.py:1179} INFO - Dependencies all met for <TaskInstance: generate_data.export_tables_to_dir manual__2022-10-14T16:33:50.014140+00:00 [queued]>
[2022-10-14 16:34:56,756] {taskinstance.py:1179} INFO - Dependencies all met for <TaskInstance: generate_data.export_tables_to_dir manual__2022-10-14T16:33:50.014140+00:00 [queued]>
[2022-10-14 16:34:56,757] {taskinstance.py:1376} INFO - 
--------------------------------------------------------------------------------
[2022-10-14 16:34:56,759] {taskinstance.py:1377} INFO - Starting attempt 2 of 2
[2022-10-14 16:34:56,760] {taskinstance.py:1378} INFO - 
--------------------------------------------------------------------------------
[2022-10-14 16:34:56,777] {taskinstance.py:1397} INFO - Executing <Task(PythonOperator): export_tables_to_dir> on 2022-10-14 16:33:50.014140+00:00
[2022-10-14 16:34:56,785] {standard_task_runner.py:52} INFO - Started process 27403 to run task
[2022-10-14 16:34:56,789] {standard_task_runner.py:79} INFO - Running: ['***', 'tasks', 'run', 'generate_data', 'export_tables_to_dir', 'manual__2022-10-14T16:33:50.014140+00:00', '--job-id', '75', '--raw', '--subdir', 'DAGS_FOLDER/generate_data.py', '--cfg-path', '/tmp/tmp4vb_yr5x', '--error-file', '/tmp/tmpzu4y1q6e']
[2022-10-14 16:34:56,792] {standard_task_runner.py:80} INFO - Job 75: Subtask export_tables_to_dir
[2022-10-14 16:34:56,876] {task_command.py:371} INFO - Running <TaskInstance: generate_data.export_tables_to_dir manual__2022-10-14T16:33:50.014140+00:00 [running]> on host 6b13e7472fb2
[2022-10-14 16:34:56,968] {taskinstance.py:1591} INFO - Exporting the following env vars:
AIRFLOW_CTX_DAG_OWNER=***
AIRFLOW_CTX_DAG_ID=generate_data
AIRFLOW_CTX_TASK_ID=export_tables_to_dir
AIRFLOW_CTX_EXECUTION_DATE=2022-10-14T16:33:50.014140+00:00
AIRFLOW_CTX_TRY_NUMBER=2
AIRFLOW_CTX_DAG_RUN_ID=manual__2022-10-14T16:33:50.014140+00:00
[2022-10-14 16:34:56,978] {export_tables.py:37} INFO - Connection to database success
[2022-10-14 16:34:56,980] {export_tables.py:120} INFO - Working on transaction
[2022-10-14 16:34:56,982] {export_tables.py:86} INFO - Exporting 200 rows into csv.
[2022-10-14 16:34:56,983] {export_tables.py:75} INFO - Path already exist, overwriting the file
[2022-10-14 16:34:56,984] {export_tables.py:96} CRITICAL - Something went wrong at exporting the table to container storage
[2022-10-14 16:34:56,985] {export_tables.py:120} INFO - Working on customer
[2022-10-14 16:34:56,987] {taskinstance.py:1909} ERROR - Task failed with exception
Traceback (most recent call last):
  File "/home/airflow/.local/lib/python3.7/site-packages/airflow/operators/python.py", line 171, in execute
    return_value = self.execute_callable()
  File "/home/airflow/.local/lib/python3.7/site-packages/airflow/operators/python.py", line 189, in execute_callable
    return self.python_callable(*self.op_args, **self.op_kwargs)
  File "/opt/airflow/dags/export_tables.py", line 121, in export
    copy_table(cursor=connection_cursor, conn=connection, path='/opt/airflow/dags/data_storage/pgdata/', table=table.get(_), days=days)
  File "/opt/airflow/dags/export_tables.py", line 85, in copy_table
    rows = count_rows(cursor, table=table)
  File "/opt/airflow/dags/export_tables.py", line 49, in count_rows
    cursor.execute(f'SELECT * FROM {table}')
psycopg2.errors.InFailedSqlTransaction: current transaction is aborted, commands ignored until end of transaction block

[2022-10-14 16:34:57,001] {taskinstance.py:1420} INFO - Marking task as FAILED. dag_id=generate_data, task_id=export_tables_to_dir, execution_date=20221014T163350, start_date=20221014T163456, end_date=20221014T163457
[2022-10-14 16:34:57,015] {standard_task_runner.py:97} ERROR - Failed to execute job 75 for task export_tables_to_dir (current transaction is aborted, commands ignored until end of transaction block
; 27403)
[2022-10-14 16:34:57,044] {local_task_job.py:156} INFO - Task exited with return code 1
[2022-10-14 16:34:57,086] {local_task_job.py:273} INFO - 0 downstream tasks scheduled from follow-on schedule check
