[2022-10-14 18:16:06,809] {taskinstance.py:1179} INFO - Dependencies all met for <TaskInstance: generate_data.generate_data manual__2022-10-14T18:16:05.533681+00:00 [queued]>
[2022-10-14 18:16:06,822] {taskinstance.py:1179} INFO - Dependencies all met for <TaskInstance: generate_data.generate_data manual__2022-10-14T18:16:05.533681+00:00 [queued]>
[2022-10-14 18:16:06,823] {taskinstance.py:1376} INFO - 
--------------------------------------------------------------------------------
[2022-10-14 18:16:06,824] {taskinstance.py:1377} INFO - Starting attempt 1 of 2
[2022-10-14 18:16:06,824] {taskinstance.py:1378} INFO - 
--------------------------------------------------------------------------------
[2022-10-14 18:16:06,839] {taskinstance.py:1397} INFO - Executing <Task(PythonOperator): generate_data> on 2022-10-14 18:16:05.533681+00:00
[2022-10-14 18:16:06,846] {standard_task_runner.py:52} INFO - Started process 416 to run task
[2022-10-14 18:16:06,851] {standard_task_runner.py:79} INFO - Running: ['***', 'tasks', 'run', 'generate_data', 'generate_data', 'manual__2022-10-14T18:16:05.533681+00:00', '--job-id', '91', '--raw', '--subdir', 'DAGS_FOLDER/generate_data.py', '--cfg-path', '/tmp/tmp9edrts0g', '--error-file', '/tmp/tmpi07cl06p']
[2022-10-14 18:16:06,853] {standard_task_runner.py:80} INFO - Job 91: Subtask generate_data
[2022-10-14 18:16:06,940] {task_command.py:371} INFO - Running <TaskInstance: generate_data.generate_data manual__2022-10-14T18:16:05.533681+00:00 [running]> on host aee033a1302b
[2022-10-14 18:16:07,033] {taskinstance.py:1591} INFO - Exporting the following env vars:
AIRFLOW_CTX_DAG_OWNER=***
AIRFLOW_CTX_DAG_ID=generate_data
AIRFLOW_CTX_TASK_ID=generate_data
AIRFLOW_CTX_EXECUTION_DATE=2022-10-14T18:16:05.533681+00:00
AIRFLOW_CTX_TRY_NUMBER=1
AIRFLOW_CTX_DAG_RUN_ID=manual__2022-10-14T18:16:05.533681+00:00
[2022-10-14 18:16:07,037] {taskinstance.py:1909} ERROR - Task failed with exception
Traceback (most recent call last):
  File "/home/airflow/.local/lib/python3.7/site-packages/airflow/operators/python.py", line 171, in execute
    return_value = self.execute_callable()
  File "/home/airflow/.local/lib/python3.7/site-packages/airflow/operators/python.py", line 189, in execute_callable
    return self.python_callable(*self.op_args, **self.op_kwargs)
  File "/opt/airflow/dags/insertion_orchestration.py", line 25, in gen_data
    days = get_days()
  File "/opt/airflow/dags/insertion_orchestration.py", line 10, in get_days
    with open(path, 'rb') as handle:
FileNotFoundError: [Errno 2] No such file or directory: '/opt/airflow/dags/data_storage/days/days.pickle'
[2022-10-14 18:16:07,051] {taskinstance.py:1420} INFO - Marking task as UP_FOR_RETRY. dag_id=generate_data, task_id=generate_data, execution_date=20221014T181605, start_date=20221014T181606, end_date=20221014T181607
[2022-10-14 18:16:07,069] {standard_task_runner.py:97} ERROR - Failed to execute job 91 for task generate_data ([Errno 2] No such file or directory: '/opt/airflow/dags/data_storage/days/days.pickle'; 416)
[2022-10-14 18:16:07,105] {local_task_job.py:156} INFO - Task exited with return code 1
[2022-10-14 18:16:07,164] {local_task_job.py:273} INFO - 0 downstream tasks scheduled from follow-on schedule check
