[2022-10-14 14:25:31,168] {taskinstance.py:1179} INFO - Dependencies all met for <TaskInstance: generate_data.generate_data scheduled__2022-10-14T14:05:43.875610+00:00 [queued]>
[2022-10-14 14:25:31,522] {taskinstance.py:1179} INFO - Dependencies all met for <TaskInstance: generate_data.generate_data scheduled__2022-10-14T14:05:43.875610+00:00 [queued]>
[2022-10-14 14:25:31,549] {taskinstance.py:1376} INFO - 
--------------------------------------------------------------------------------
[2022-10-14 14:25:31,554] {taskinstance.py:1377} INFO - Starting attempt 2 of 2
[2022-10-14 14:25:31,557] {taskinstance.py:1378} INFO - 
--------------------------------------------------------------------------------
[2022-10-14 14:25:32,114] {taskinstance.py:1397} INFO - Executing <Task(PythonOperator): generate_data> on 2022-10-14 14:05:43.875610+00:00
[2022-10-14 14:25:32,277] {standard_task_runner.py:52} INFO - Started process 22184 to run task
[2022-10-14 14:25:32,388] {standard_task_runner.py:79} INFO - Running: ['***', 'tasks', 'run', 'generate_data', 'generate_data', 'scheduled__2022-10-14T14:05:43.875610+00:00', '--job-id', '45', '--raw', '--subdir', 'DAGS_FOLDER/generate_data.py', '--cfg-path', '/tmp/tmp1deruphf', '--error-file', '/tmp/tmp2nxi5xd4']
[2022-10-14 14:25:32,442] {standard_task_runner.py:80} INFO - Job 45: Subtask generate_data
[2022-10-14 14:25:35,841] {task_command.py:371} INFO - Running <TaskInstance: generate_data.generate_data scheduled__2022-10-14T14:05:43.875610+00:00 [running]> on host 6b13e7472fb2
[2022-10-14 14:25:39,243] {taskinstance.py:1591} INFO - Exporting the following env vars:
AIRFLOW_CTX_DAG_OWNER=***
AIRFLOW_CTX_DAG_ID=generate_data
AIRFLOW_CTX_TASK_ID=generate_data
AIRFLOW_CTX_EXECUTION_DATE=2022-10-14T14:05:43.875610+00:00
AIRFLOW_CTX_TRY_NUMBER=2
AIRFLOW_CTX_DAG_RUN_ID=scheduled__2022-10-14T14:05:43.875610+00:00
[2022-10-14 14:25:39,680] {db_conn.py:23} INFO - Connection to database success
[2022-10-14 14:25:41,127] {insertion_factory.py:41} CRITICAL - <class 'RecursionError'>
[2022-10-14 14:25:41,153] {insertion_factory.py:42} CRITICAL - maximum recursion depth exceeded while calling a Python object
[2022-10-14 14:25:41,173] {insertion_factory.py:43} CRITICAL - Insertion into database failed, check params.
[2022-10-14 14:25:41,232] {logging_mixin.py:115} INFO - Generating jsonline: 1
[2022-10-14 14:25:42,537] {taskinstance.py:1909} ERROR - Task failed with exception
Traceback (most recent call last):
  File "/home/airflow/.local/lib/python3.7/site-packages/airflow/operators/python.py", line 171, in execute
    return_value = self.execute_callable()
  File "/home/airflow/.local/lib/python3.7/site-packages/airflow/operators/python.py", line 189, in execute_callable
    return self.python_callable(*self.op_args, **self.op_kwargs)
  File "/opt/airflow/dags/insertion_orchestration.py", line 34, in gen_data
    jf.generate_jsonlines(n_lines=insertions, days= days)
  File "/opt/airflow/dags/json_factory.py", line 22, in generate_jsonlines
    id = ID.get_id(dict_ids = ids)
  File "/opt/airflow/dags/id_loader.py", line 35, in get_id
    return get_id(dict_ids)
  File "/opt/airflow/dags/id_loader.py", line 35, in get_id
    return get_id(dict_ids)
  File "/opt/airflow/dags/id_loader.py", line 35, in get_id
    return get_id(dict_ids)
  [Previous line repeated 929 more times]
  File "/opt/airflow/dags/id_loader.py", line 29, in get_id
    key, value = random.choice(list(dict_ids.items()))
  File "/usr/local/lib/python3.7/random.py", line 259, in choice
    i = self._randbelow(len(seq))
  File "/usr/local/lib/python3.7/random.py", line 232, in _randbelow
    if type(random) is BuiltinMethod or type(getrandbits) is Method:
RecursionError: maximum recursion depth exceeded while calling a Python object
[2022-10-14 14:25:42,812] {taskinstance.py:1420} INFO - Marking task as FAILED. dag_id=generate_data, task_id=generate_data, execution_date=20221014T140543, start_date=20221014T142531, end_date=20221014T142542
[2022-10-14 14:25:43,472] {standard_task_runner.py:97} ERROR - Failed to execute job 45 for task generate_data (maximum recursion depth exceeded while calling a Python object; 22184)
[2022-10-14 14:25:44,162] {local_task_job.py:156} INFO - Task exited with return code 1
[2022-10-14 14:25:44,621] {local_task_job.py:273} INFO - 0 downstream tasks scheduled from follow-on schedule check
