[2022-10-17 17:30:18,154] {taskinstance.py:1179} INFO - Dependencies all met for <TaskInstance: generate_data.export_tables_to_dir manual__2022-10-17T17:30:12.603253+00:00 [queued]>
[2022-10-17 17:30:18,171] {taskinstance.py:1179} INFO - Dependencies all met for <TaskInstance: generate_data.export_tables_to_dir manual__2022-10-17T17:30:12.603253+00:00 [queued]>
[2022-10-17 17:30:18,172] {taskinstance.py:1376} INFO - 
--------------------------------------------------------------------------------
[2022-10-17 17:30:18,172] {taskinstance.py:1377} INFO - Starting attempt 1 of 2
[2022-10-17 17:30:18,173] {taskinstance.py:1378} INFO - 
--------------------------------------------------------------------------------
[2022-10-17 17:30:18,195] {taskinstance.py:1397} INFO - Executing <Task(PythonOperator): export_tables_to_dir> on 2022-10-17 17:30:12.603253+00:00
[2022-10-17 17:30:18,205] {standard_task_runner.py:52} INFO - Started process 46588 to run task
[2022-10-17 17:30:18,210] {standard_task_runner.py:79} INFO - Running: ['***', 'tasks', 'run', 'generate_data', 'export_tables_to_dir', 'manual__2022-10-17T17:30:12.603253+00:00', '--job-id', '411', '--raw', '--subdir', 'DAGS_FOLDER/generate_data.py', '--cfg-path', '/tmp/tmpsfy3hngb', '--error-file', '/tmp/tmpu5us9dez']
[2022-10-17 17:30:18,214] {standard_task_runner.py:80} INFO - Job 411: Subtask export_tables_to_dir
[2022-10-17 17:30:18,316] {task_command.py:371} INFO - Running <TaskInstance: generate_data.export_tables_to_dir manual__2022-10-17T17:30:12.603253+00:00 [running]> on host 614e96fbdf07
[2022-10-17 17:30:18,419] {taskinstance.py:1591} INFO - Exporting the following env vars:
AIRFLOW_CTX_DAG_OWNER=***
AIRFLOW_CTX_DAG_ID=generate_data
AIRFLOW_CTX_TASK_ID=export_tables_to_dir
AIRFLOW_CTX_EXECUTION_DATE=2022-10-17T17:30:12.603253+00:00
AIRFLOW_CTX_TRY_NUMBER=1
AIRFLOW_CTX_DAG_RUN_ID=manual__2022-10-17T17:30:12.603253+00:00
[2022-10-17 17:30:18,433] {export_tables.py:37} INFO - Connection to database success
[2022-10-17 17:30:18,436] {export_tables.py:127} INFO - Working on transaction
[2022-10-17 17:30:18,441] {export_tables.py:90} INFO - Exporting 2001 rows into csv.
[2022-10-17 17:30:18,443] {export_tables.py:78} INFO - Creating path /opt/transaction/2022-10-17
[2022-10-17 17:30:18,445] {export_tables.py:101} CRITICAL - <class 'AttributeError'>
[2022-10-17 17:30:18,446] {export_tables.py:102} CRITICAL - 'FileNotFoundError' object has no attribute '__clas__'
[2022-10-17 17:30:18,447] {export_tables.py:103} CRITICAL - Something went wrong at exporting the table to container storage
[2022-10-17 17:30:18,448] {export_tables.py:127} INFO - Working on customer
[2022-10-17 17:30:18,454] {export_tables.py:90} INFO - Exporting 2001 rows into csv.
[2022-10-17 17:30:18,456] {export_tables.py:78} INFO - Creating path /opt/customer/2022-10-17
[2022-10-17 17:30:18,456] {export_tables.py:101} CRITICAL - <class 'AttributeError'>
[2022-10-17 17:30:18,457] {export_tables.py:102} CRITICAL - 'FileNotFoundError' object has no attribute '__clas__'
[2022-10-17 17:30:18,458] {export_tables.py:103} CRITICAL - Something went wrong at exporting the table to container storage
[2022-10-17 17:30:18,459] {export_tables.py:113} INFO - Both cursor and conn closed successfully
[2022-10-17 17:30:18,460] {export_tables.py:134} INFO - Both thables export successfully
[2022-10-17 17:30:18,461] {python.py:173} INFO - Done. Returned value was: None
[2022-10-17 17:30:18,479] {taskinstance.py:1420} INFO - Marking task as SUCCESS. dag_id=generate_data, task_id=export_tables_to_dir, execution_date=20221017T173012, start_date=20221017T173018, end_date=20221017T173018
[2022-10-17 17:30:18,544] {local_task_job.py:156} INFO - Task exited with return code 0
[2022-10-17 17:30:18,598] {local_task_job.py:273} INFO - 0 downstream tasks scheduled from follow-on schedule check
