[2022-10-24T18:20:16.239+0000] {taskinstance.py:1165} INFO - Dependencies all met for <TaskInstance: unify_datasets.load_and_transform_unified_data manual__2022-10-24T18:18:53.023703+00:00 [queued]>
[2022-10-24T18:20:16.288+0000] {taskinstance.py:1165} INFO - Dependencies all met for <TaskInstance: unify_datasets.load_and_transform_unified_data manual__2022-10-24T18:18:53.023703+00:00 [queued]>
[2022-10-24T18:20:16.291+0000] {taskinstance.py:1362} INFO - 
--------------------------------------------------------------------------------
[2022-10-24T18:20:16.293+0000] {taskinstance.py:1363} INFO - Starting attempt 1 of 2
[2022-10-24T18:20:16.295+0000] {taskinstance.py:1364} INFO - 
--------------------------------------------------------------------------------
[2022-10-24T18:20:16.360+0000] {taskinstance.py:1383} INFO - Executing <Task(PythonOperator): load_and_transform_unified_data> on 2022-10-24 18:18:53.023703+00:00
[2022-10-24T18:20:16.377+0000] {standard_task_runner.py:54} INFO - Started process 5534 to run task
[2022-10-24T18:20:16.393+0000] {standard_task_runner.py:82} INFO - Running: ['***', 'tasks', 'run', 'unify_datasets', 'load_and_transform_unified_data', 'manual__2022-10-24T18:18:53.023703+00:00', '--job-id', '534', '--raw', '--subdir', 'DAGS_FOLDER/load_and_unify_datasets.py', '--cfg-path', '/tmp/tmpc07t6abm']
[2022-10-24T18:20:16.396+0000] {standard_task_runner.py:83} INFO - Job 534: Subtask load_and_transform_unified_data
[2022-10-24T18:20:16.400+0000] {dagbag.py:525} INFO - Filling up the DagBag from /opt/***/dags/load_and_unify_datasets.py
[2022-10-24T18:20:16.685+0000] {task_command.py:384} INFO - Running <TaskInstance: unify_datasets.load_and_transform_unified_data manual__2022-10-24T18:18:53.023703+00:00 [running]> on host c94e224fed05
[2022-10-24T18:20:16.983+0000] {taskinstance.py:1592} INFO - Exporting the following env vars:
AIRFLOW_CTX_DAG_OWNER=***
AIRFLOW_CTX_DAG_ID=unify_datasets
AIRFLOW_CTX_TASK_ID=load_and_transform_unified_data
AIRFLOW_CTX_EXECUTION_DATE=2022-10-24T18:18:53.023703+00:00
AIRFLOW_CTX_TRY_NUMBER=1
AIRFLOW_CTX_DAG_RUN_ID=manual__2022-10-24T18:18:53.023703+00:00
[2022-10-24T18:21:07.799+0000] {taskinstance.py:1851} ERROR - Task failed with exception
Traceback (most recent call last):
  File "/home/airflow/.local/lib/python3.7/site-packages/airflow/operators/python.py", line 175, in execute
    return_value = self.execute_callable()
  File "/home/airflow/.local/lib/python3.7/site-packages/airflow/operators/python.py", line 193, in execute_callable
    return self.python_callable(*self.op_args, **self.op_kwargs)
  File "/opt/airflow/dags/pyspark_scripts.py", line 184, in transform_data
    unified_model = dump_df.select('id', 'customer_id', 'store_id', 'type', 'float_amount', 'customer_first_name', 'customer_last_name', 'phone_number', 'address', 't_timestamp')
  File "/home/airflow/.local/lib/python3.7/site-packages/pyspark/sql/dataframe.py", line 2023, in select
    jdf = self._jdf.select(self._jcols(*cols))
  File "/home/airflow/.local/lib/python3.7/site-packages/py4j/java_gateway.py", line 1322, in __call__
    answer, self.gateway_client, self.target_id, self.name)
  File "/home/airflow/.local/lib/python3.7/site-packages/pyspark/sql/utils.py", line 196, in deco
    raise converted from None
pyspark.sql.utils.AnalysisException: Column 'customer_id' does not exist. Did you mean one of the following? [store_id, customer_first_name, customer_last_name, id, t_timestamp, timestamp, type, amount, float_amount];
'Project [id#0L, 'customer_id, store_id#2L, type#1L, float_amount#15, customer_first_name#4, customer_last_name#5, 'phone_number, 'address, t_timestamp#26]
+- Project [id#0L, type#1L, store_id#2L, amount#3, customer_first_name#4, customer_last_name#5, timestamp#6, float_amount#15, <lambda>(timestamp#6)#25 AS t_timestamp#26]
   +- Project [id#0L, type#1L, store_id#2L, amount#3, customer_first_name#4, customer_last_name#5, timestamp#6, <lambda>(amount#3)#14 AS float_amount#15]
      +- Relation [id#0L,type#1L,store_id#2L,amount#3,customer_first_name#4,customer_last_name#5,timestamp#6] parquet

[2022-10-24T18:21:07.946+0000] {taskinstance.py:1406} INFO - Marking task as UP_FOR_RETRY. dag_id=unify_datasets, task_id=load_and_transform_unified_data, execution_date=20221024T181853, start_date=20221024T182016, end_date=20221024T182107
[2022-10-24T18:21:08.050+0000] {standard_task_runner.py:107} ERROR - Failed to execute job 534 for task load_and_transform_unified_data (Column 'customer_id' does not exist. Did you mean one of the following? [store_id, customer_first_name, customer_last_name, id, t_timestamp, timestamp, type, amount, float_amount];
'Project [id#0L, 'customer_id, store_id#2L, type#1L, float_amount#15, customer_first_name#4, customer_last_name#5, 'phone_number, 'address, t_timestamp#26]
+- Project [id#0L, type#1L, store_id#2L, amount#3, customer_first_name#4, customer_last_name#5, timestamp#6, float_amount#15, <lambda>(timestamp#6)#25 AS t_timestamp#26]
   +- Project [id#0L, type#1L, store_id#2L, amount#3, customer_first_name#4, customer_last_name#5, timestamp#6, <lambda>(amount#3)#14 AS float_amount#15]
      +- Relation [id#0L,type#1L,store_id#2L,amount#3,customer_first_name#4,customer_last_name#5,timestamp#6] parquet
; 5534)
[2022-10-24T18:21:08.129+0000] {local_task_job.py:164} INFO - Task exited with return code 1
[2022-10-24T18:21:08.241+0000] {local_task_job.py:273} INFO - 0 downstream tasks scheduled from follow-on schedule check
